2023-07-06 16:39:50,758 [ERROR] Exception while creating Pool: 2003: Can't connect to MySQL server on '%-.100s:%u' (%s) (Warning: %u format: a number is required, not str)
Traceback (most recent call last):
  File "/Library/Python/3.8/site-packages/mysql/connector/network.py", line 570, in open_connection
    addrinfos = socket.getaddrinfo(
  File "/Library/Developer/CommandLineTools/Library/Frameworks/Python3.framework/Versions/3.8/lib/python3.8/socket.py", line 918, in getaddrinfo
    for res in _socket.getaddrinfo(host, port, family, type, proto, flags):
socket.gaierror: [Errno 8] nodename nor servname provided, or not known

The above exception was the direct cause of the following exception:

Traceback (most recent call last):
  File "/Users/Vas/Documents/Coding_Projects/Exhibition_Stats/Exhibition_Statistics/backend/global_variables.py", line 32, in <module>
    db_connection_pool = pooling.MySQLConnectionPool(
  File "/Library/Python/3.8/site-packages/mysql/connector/pooling.py", line 430, in __init__
    self.add_connection()
  File "/Library/Python/3.8/site-packages/mysql/connector/pooling.py", line 538, in add_connection
    cnx = connect(**self._cnx_config)  # type: ignore[assignment]
  File "/Library/Python/3.8/site-packages/mysql/connector/pooling.py", line 294, in connect
    return MySQLConnection(*args, **kwargs)
  File "/Library/Python/3.8/site-packages/mysql/connector/connection.py", line 164, in __init__
    self.connect(**kwargs)
  File "/Library/Python/3.8/site-packages/mysql/connector/abstracts.py", line 1181, in connect
    self._open_connection()
  File "/Library/Python/3.8/site-packages/mysql/connector/connection.py", line 570, in _open_connection
    self._socket.open_connection()
  File "/Library/Python/3.8/site-packages/mysql/connector/network.py", line 590, in open_connection
    raise InterfaceError(
mysql.connector.errors.InterfaceError: 2003: Can't connect to MySQL server on '%-.100s:%u' (%s) (Warning: %u format: a number is required, not str)
