2023-07-18 16:26:29,946 [INFO] Starting Backend...
2023-07-18 16:26:29,947 [INFO] Recording broker trafic subscribed to: tokenStations/+/onScan
2023-07-18 16:26:29,953 [INFO] process_daily_scans function was called...
2023-07-18 16:26:29,972 [INFO] Succesfully connected to DB using Pool: db_pool_scans_processing
2023-07-18 16:26:29,977 [INFO] Succesfully connected to MySQL Server: 8.0.33
2023-07-18 16:26:29,979 [INFO] Parsing daily scans to DB...
2023-07-18 16:26:30,034 [ERROR] INSERT : 
Traceback (most recent call last):
  File "/usr/local/lib/python3.9/site-packages/mysql/connector/connection_cext.py", line 611, in cmd_query
    self._cmysql.query(
_mysql_connector.MySQLInterfaceError: Duplicate entry '2023-07-18-gtTokenGenetics0-E0040150B18F35CB' for key 'scans.scan_UNIQUE_combi'

The above exception was the direct cause of the following exception:

Traceback (most recent call last):
  File "/backend/scans_to_db.py", line 103, in process_daily_scans
    cursor.execute(query, values)
  File "/usr/local/lib/python3.9/site-packages/mysql/connector/cursor_cext.py", line 330, in execute
    result = self._cnx.cmd_query(
  File "/usr/local/lib/python3.9/site-packages/mysql/connector/connection_cext.py", line 619, in cmd_query
    raise get_mysql_exception(
mysql.connector.errors.IntegrityError: 1062 (23000): Duplicate entry '2023-07-18-gtTokenGenetics0-E0040150B18F35CB' for key 'scans.scan_UNIQUE_combi'
2023-07-18 16:26:30,044 [ERROR] INSERT : 
Traceback (most recent call last):
  File "/usr/local/lib/python3.9/site-packages/mysql/connector/connection_cext.py", line 611, in cmd_query
    self._cmysql.query(
_mysql_connector.MySQLInterfaceError: Duplicate entry '2023-07-18-gtTokenGenetics0-E0040150B18F35CB' for key 'scans.scan_UNIQUE_combi'

The above exception was the direct cause of the following exception:

Traceback (most recent call last):
  File "/backend/scans_to_db.py", line 103, in process_daily_scans
    cursor.execute(query, values)
  File "/usr/local/lib/python3.9/site-packages/mysql/connector/cursor_cext.py", line 330, in execute
    result = self._cnx.cmd_query(
  File "/usr/local/lib/python3.9/site-packages/mysql/connector/connection_cext.py", line 619, in cmd_query
    raise get_mysql_exception(
mysql.connector.errors.IntegrityError: 1062 (23000): Duplicate entry '2023-07-18-gtTokenGenetics0-E0040150B18F35CB' for key 'scans.scan_UNIQUE_combi'
2023-07-18 16:26:30,050 [ERROR] INSERT : 
Traceback (most recent call last):
  File "/usr/local/lib/python3.9/site-packages/mysql/connector/connection_cext.py", line 611, in cmd_query
    self._cmysql.query(
_mysql_connector.MySQLInterfaceError: Duplicate entry '2023-07-18-gtTokenGenetics0-E0040150B18F35CB' for key 'scans.scan_UNIQUE_combi'

The above exception was the direct cause of the following exception:

Traceback (most recent call last):
  File "/backend/scans_to_db.py", line 103, in process_daily_scans
    cursor.execute(query, values)
  File "/usr/local/lib/python3.9/site-packages/mysql/connector/cursor_cext.py", line 330, in execute
    result = self._cnx.cmd_query(
  File "/usr/local/lib/python3.9/site-packages/mysql/connector/connection_cext.py", line 619, in cmd_query
    raise get_mysql_exception(
mysql.connector.errors.IntegrityError: 1062 (23000): Duplicate entry '2023-07-18-gtTokenGenetics0-E0040150B18F35CB' for key 'scans.scan_UNIQUE_combi'
2023-07-18 16:26:30,082 [ERROR] INSERT : 
Traceback (most recent call last):
  File "/usr/local/lib/python3.9/site-packages/mysql/connector/connection_cext.py", line 611, in cmd_query
    self._cmysql.query(
_mysql_connector.MySQLInterfaceError: Duplicate entry '2023-07-18-wbTokenVoteC-E0040150B18F3AA8' for key 'scans.scan_UNIQUE_combi'

The above exception was the direct cause of the following exception:

Traceback (most recent call last):
  File "/backend/scans_to_db.py", line 103, in process_daily_scans
    cursor.execute(query, values)
  File "/usr/local/lib/python3.9/site-packages/mysql/connector/cursor_cext.py", line 330, in execute
    result = self._cnx.cmd_query(
  File "/usr/local/lib/python3.9/site-packages/mysql/connector/connection_cext.py", line 619, in cmd_query
    raise get_mysql_exception(
mysql.connector.errors.IntegrityError: 1062 (23000): Duplicate entry '2023-07-18-wbTokenVoteC-E0040150B18F3AA8' for key 'scans.scan_UNIQUE_combi'
2023-07-18 16:26:30,089 [ERROR] INSERT : 
Traceback (most recent call last):
  File "/usr/local/lib/python3.9/site-packages/mysql/connector/connection_cext.py", line 611, in cmd_query
    self._cmysql.query(
_mysql_connector.MySQLInterfaceError: Duplicate entry '2023-07-18-wbTokenVoteA-E0040150B18F3AA8' for key 'scans.scan_UNIQUE_combi'

The above exception was the direct cause of the following exception:

Traceback (most recent call last):
  File "/backend/scans_to_db.py", line 103, in process_daily_scans
    cursor.execute(query, values)
  File "/usr/local/lib/python3.9/site-packages/mysql/connector/cursor_cext.py", line 330, in execute
    result = self._cnx.cmd_query(
  File "/usr/local/lib/python3.9/site-packages/mysql/connector/connection_cext.py", line 619, in cmd_query
    raise get_mysql_exception(
mysql.connector.errors.IntegrityError: 1062 (23000): Duplicate entry '2023-07-18-wbTokenVoteA-E0040150B18F3AA8' for key 'scans.scan_UNIQUE_combi'
2023-07-18 16:26:30,115 [INFO] Parsing Token Scans Completed Succesfully!
2023-07-18 16:26:30,116 [INFO] After today's parsing of scans in DB number of excesive/multiple scans is: 5
2023-07-18 16:26:30,116 [INFO] Waiting 12 hours until checking time for parsing token scans again...
2023-07-18 16:48:18,608 [INFO] Starting Backend...
2023-07-18 16:48:18,610 [INFO] Recording broker trafic subscribed to: tokenStations/+/onScan
2023-07-18 16:48:18,615 [INFO] process_daily_scans function was called...
2023-07-18 16:48:18,631 [INFO] Succesfully connected to DB using Pool: db_pool_scans_processing
2023-07-18 16:48:18,632 [INFO] Succesfully connected to MySQL Server: 8.0.33
2023-07-18 16:48:18,633 [INFO] Parsing daily scans to DB...
2023-07-18 16:48:18,674 [ERROR] INSERT : 
Traceback (most recent call last):
  File "/usr/local/lib/python3.9/site-packages/mysql/connector/connection_cext.py", line 611, in cmd_query
    self._cmysql.query(
_mysql_connector.MySQLInterfaceError: Duplicate entry '2023-07-18-gtTokenGenetics0-E0040150B18F35CB' for key 'scans.scan_UNIQUE_combi'

The above exception was the direct cause of the following exception:

Traceback (most recent call last):
  File "/backend/scans_to_db.py", line 103, in process_daily_scans
    cursor.execute(query, values)
  File "/usr/local/lib/python3.9/site-packages/mysql/connector/cursor_cext.py", line 330, in execute
    result = self._cnx.cmd_query(
  File "/usr/local/lib/python3.9/site-packages/mysql/connector/connection_cext.py", line 619, in cmd_query
    raise get_mysql_exception(
mysql.connector.errors.IntegrityError: 1062 (23000): Duplicate entry '2023-07-18-gtTokenGenetics0-E0040150B18F35CB' for key 'scans.scan_UNIQUE_combi'
2023-07-18 16:48:18,683 [ERROR] INSERT : 
Traceback (most recent call last):
  File "/usr/local/lib/python3.9/site-packages/mysql/connector/connection_cext.py", line 611, in cmd_query
    self._cmysql.query(
_mysql_connector.MySQLInterfaceError: Duplicate entry '2023-07-18-gtTokenGenetics0-E0040150B18F35CB' for key 'scans.scan_UNIQUE_combi'

The above exception was the direct cause of the following exception:

Traceback (most recent call last):
  File "/backend/scans_to_db.py", line 103, in process_daily_scans
    cursor.execute(query, values)
  File "/usr/local/lib/python3.9/site-packages/mysql/connector/cursor_cext.py", line 330, in execute
    result = self._cnx.cmd_query(
  File "/usr/local/lib/python3.9/site-packages/mysql/connector/connection_cext.py", line 619, in cmd_query
    raise get_mysql_exception(
mysql.connector.errors.IntegrityError: 1062 (23000): Duplicate entry '2023-07-18-gtTokenGenetics0-E0040150B18F35CB' for key 'scans.scan_UNIQUE_combi'
2023-07-18 16:48:18,699 [ERROR] INSERT : 
Traceback (most recent call last):
  File "/usr/local/lib/python3.9/site-packages/mysql/connector/connection_cext.py", line 611, in cmd_query
    self._cmysql.query(
_mysql_connector.MySQLInterfaceError: Duplicate entry '2023-07-18-gtTokenGenetics0-E0040150B18F35CB' for key 'scans.scan_UNIQUE_combi'

The above exception was the direct cause of the following exception:

Traceback (most recent call last):
  File "/backend/scans_to_db.py", line 103, in process_daily_scans
    cursor.execute(query, values)
  File "/usr/local/lib/python3.9/site-packages/mysql/connector/cursor_cext.py", line 330, in execute
    result = self._cnx.cmd_query(
  File "/usr/local/lib/python3.9/site-packages/mysql/connector/connection_cext.py", line 619, in cmd_query
    raise get_mysql_exception(
mysql.connector.errors.IntegrityError: 1062 (23000): Duplicate entry '2023-07-18-gtTokenGenetics0-E0040150B18F35CB' for key 'scans.scan_UNIQUE_combi'
2023-07-18 16:48:18,725 [ERROR] INSERT : 
Traceback (most recent call last):
  File "/usr/local/lib/python3.9/site-packages/mysql/connector/connection_cext.py", line 611, in cmd_query
    self._cmysql.query(
_mysql_connector.MySQLInterfaceError: Duplicate entry '2023-07-18-wbTokenVoteC-E0040150B18F3AA8' for key 'scans.scan_UNIQUE_combi'

The above exception was the direct cause of the following exception:

Traceback (most recent call last):
  File "/backend/scans_to_db.py", line 103, in process_daily_scans
    cursor.execute(query, values)
  File "/usr/local/lib/python3.9/site-packages/mysql/connector/cursor_cext.py", line 330, in execute
    result = self._cnx.cmd_query(
  File "/usr/local/lib/python3.9/site-packages/mysql/connector/connection_cext.py", line 619, in cmd_query
    raise get_mysql_exception(
mysql.connector.errors.IntegrityError: 1062 (23000): Duplicate entry '2023-07-18-wbTokenVoteC-E0040150B18F3AA8' for key 'scans.scan_UNIQUE_combi'
2023-07-18 16:48:18,730 [ERROR] INSERT : 
Traceback (most recent call last):
  File "/usr/local/lib/python3.9/site-packages/mysql/connector/connection_cext.py", line 611, in cmd_query
    self._cmysql.query(
_mysql_connector.MySQLInterfaceError: Duplicate entry '2023-07-18-wbTokenVoteA-E0040150B18F3AA8' for key 'scans.scan_UNIQUE_combi'

The above exception was the direct cause of the following exception:

Traceback (most recent call last):
  File "/backend/scans_to_db.py", line 103, in process_daily_scans
    cursor.execute(query, values)
  File "/usr/local/lib/python3.9/site-packages/mysql/connector/cursor_cext.py", line 330, in execute
    result = self._cnx.cmd_query(
  File "/usr/local/lib/python3.9/site-packages/mysql/connector/connection_cext.py", line 619, in cmd_query
    raise get_mysql_exception(
mysql.connector.errors.IntegrityError: 1062 (23000): Duplicate entry '2023-07-18-wbTokenVoteA-E0040150B18F3AA8' for key 'scans.scan_UNIQUE_combi'
2023-07-18 16:48:18,744 [INFO] Parsing Token Scans Completed Succesfully!
2023-07-18 16:48:18,744 [INFO] After today's parsing of scans in DB number of excesive/multiple scans is: 5
2023-07-18 16:48:18,745 [INFO] Waiting 12 hours until checking time for parsing token scans again...
