2023-11-08 19:12:47,601 [INFO] Starting Backend...
2023-11-08 19:12:47,602 [INFO] Recording broker trafic subscribed to: tokenStations/+/onScan
2023-11-08 19:12:47,607 [INFO] process_daily_scans function was called...
2023-11-08 19:12:47,666 [INFO] Succesfully connected to DB using Pool: db_pool_scans_processing
2023-11-08 19:12:47,667 [INFO] Succesfully connected to MySQL Server: 8.0.33
2023-11-08 19:12:47,668 [INFO] Parsing daily scans to DB...
2023-11-08 19:12:47,732 [ERROR] INSERT : 
Traceback (most recent call last):
  File "/usr/local/lib/python3.9/site-packages/mysql/connector/connection_cext.py", line 633, in cmd_query
    self._cmysql.query(
_mysql_connector.MySQLInterfaceError: Duplicate entry '2023-11-08-gtTokenGenetics0-E0040150B08EE6D5' for key 'scans.scan_UNIQUE_combi'

The above exception was the direct cause of the following exception:

Traceback (most recent call last):
  File "/backend/scans_to_db.py", line 106, in process_daily_scans
    cursor.execute(query, values)
  File "/usr/local/lib/python3.9/site-packages/mysql/connector/cursor_cext.py", line 330, in execute
    result = self._cnx.cmd_query(
  File "/usr/local/lib/python3.9/site-packages/mysql/connector/opentelemetry/context_propagation.py", line 77, in wrapper
    return method(cnx, *args, **kwargs)
  File "/usr/local/lib/python3.9/site-packages/mysql/connector/connection_cext.py", line 641, in cmd_query
    raise get_mysql_exception(
mysql.connector.errors.IntegrityError: 1062 (23000): Duplicate entry '2023-11-08-gtTokenGenetics0-E0040150B08EE6D5' for key 'scans.scan_UNIQUE_combi'
2023-11-08 19:12:47,750 [INFO] Parsing Token Scans Completed Succesfully!
2023-11-08 19:12:47,751 [INFO] After today's parsing of scans in DB number of excesive/multiple scans is: 1
2023-11-08 19:12:47,751 [INFO] Waiting 12 hours until checking time for parsing token scans again...
